Workbook

Sheet 迭代系统优化项
A1: 序号 | B1: 模块名称 | C1: 需求 | D1: 设置逻辑
A2: 1 | B2: 测算系统-数据审视-新增一个“寻找替代料“ | C2: 新增一个模块“寻找替代料“，关联PLM系统 | D2: 系统根据“物料描述”或者PN，模糊搜索后，给出相似物料可行性替代料的物料信息的显示结果，可支持批量导入需要查询的物料，同时查询完可以批量导出系统推荐可替代物料信息
A3: 2 | B3: 测算系统-BOM总表 | C3: 添加"备件大类I级"字段， | D3: 新增字段，默认加入最后一列，关联测算系统-物料基础数据表，根据物料代码关联出备件大类I级
A4: ×4 | B4: 测算系统-生产po单数据源 | C4: 关联“信创生产协同系统”，显示所需项目的配置信息 | D4: 点击configno，系统根据所点击configno，找到对应“触发生产批次号”，再关联跳转至信创生产协同系统中的“生产项目批次总览”，找到相同触发生产批次号和“configno”，根据项目信息也跳转显示出对应“configno”配置信息，详见如下图
A5: 5 | B5: 欠料调拨总表 | C5: ①产品ii级分类调整最后一列。②在武汉总库库存后面，新增3个字段分别为“采购在途”，“转储在途”，“RMA在途”，“WHBJ库存”，根据捆绑料号到测算系统对应模块下取捆绑料号汇总之后的数量 | D5: ①产品ii级分类调整最后一列。②在武汉总库库存后面，新增3个字段分别为“采购在途”，“转储在途”，“RMA在途”，“WHBJ库存”，根据捆绑料号到测算系统对应模块下取捆绑料号汇总之后的数量
A6: 6 | B6: 鲲鹏日报 | C6: 新增“可售库存数量” | D6: 新增字段，默认加入最后一列，关联DI系统里面“可售库存数量”
A7: 7 | B7: 工厂物料清单，设置每日夜间24:00自动刷新一次
A8: 9 | B8: 欠料调拨总表 | C8: 增加 “是否过保”字段的抓取
A10: 3 | B10: 信创报表-基础数据报表-服务中心备件削价清单 | C10: 添加产品Ii级分类和产品Iii级分类和备件大类和备件大类I类字段， | D10: 新增字段，默认加入最后一列，优先通过物料编码（削价物料编号不带-，需要后台转换一致），通过物料编号，关联测算系统-物料基础数据表。如物料编号抓不到，再通过捆绑料号抓，
B11: 信创报表-基础数据报表-服务中心备件削价概览 | C11: 自动获取产品线，并计算个产品线数据。服务器还是需要有个汇总
A12: 8 | B12: 计算维修收发货表-分类名称自动取值。且新增 | C12: 计算维修收发货表-分类名称改成“备件大类”自动取值。添加产品Ii级分类和产品Iii级分类和备件大类I类4个字段， | D12: 分类名称改成“备件大类”且从备件测算系统物料基础表自动取值。最后一列后面加上产品Ii级分类和产品Iii级分类和备件大类I类3个字段，
A87: 需求⑥

Sheet PLM替代表
A1: PLM系统导出字段 | B1: PLM系统导出字段 | C1: PLM系统导出字段 | D1: PLM系统导出字段 | E1: 美丽新增字段 | F1: 美丽新增字段 | G1: 美丽新增字段 | H1: 美丽新增字段 | I1: 美丽新增字段 | J1: 数量 | K1: BOM类型 | L1: 优先级 | M1: 物料类型 | N1: 有效性 | O1: 根节点PARTNO | P1: 零件PARTNO | Q1: 层级号 | R1: 物料名称 | S1: 单位 | T1: 外部料号 | U1: 旧Part.NO | V1: 板位号 | W1: 主文件 | X1: 类型 | Y1: 规格 | Z1: 美丽新增字段 | AA1: 美丽新增字段
A2: 根节点SAP.No | B2: 根节点中文描述 | C2: 子节点SAP.NO | D2: 子节点中文描述 | E2: 供应商PN码 | F2: 捆绑料号 | G2: BOM总表是否存在 | H2: 武汉库存量 | I2: WHBJ库存 | J2: PLM系统导出字段 | K2: PLM系统导出字段 | L2: PLM系统导出字段 | M2: PLM系统导出字段 | N2: PLM系统导出字段 | O2: PLM系统导出字段 | P2: PLM系统导出字段 | Q2: PLM系统导出字段 | R2: PLM系统导出字段 | S2: PLM系统导出字段 | T2: PLM系统导出字段 | U2: PLM系统导出字段 | V2: PLM系统导出字段 | W2: PLM系统导出字段 | X2: PLM系统导出字段 | Y2: PLM系统导出字段 | Z2: 产品Ⅱ级分类 | AA2: 产品Ⅲ级分类
E3: 根据C列子节点SAP.NO，2个条件，优先①关联测算系统-物料基础数据--物料代码，得出供应商PN码。②，如果①不满足则执行②，备件测算系统-工厂物料清单-物料代码--得出工业标准描述（当有多个“工业标准描述”情况下，选取字符最长那个，比如302-003848，则选取“J07T6SBLYACACDEDBB”）。 | F3: 根据C列子节点SAP.NO，关联测算系统-捆绑料号，如匹配没有的，则显示空 | G3: 根据C列子节点SAP.NO，关联备件测算系统BOM总表，能关联上，则显示“是”，关联不上，则显示“否” | H3: 根据C列子节点SAP.NO，关联测算系统-各库区库存中“武汉”库存数量 | I3: 根据C列子节点SAP.NO，关联测算系统-各库区库存中“WHBJ”库存数量 | Z3: 根据C列子节点SAP.NO,抓取PLM系统的产品Ⅱ级分类，优先测算系统-物料基础数据抓，如果物料基础数据没有，再到PLM系统抓 | AA3: 根据C列子节点SAP.NO,抓取PLM系统的产品Ⅲ级分类
A4: 69-001976 | B4: Atlas300V视频x16-24G-72W-SWHHHL半高+全高挡片 | C4: 302-002025 | D4: Atlas300V视频x16-24G-72W-SWHHHL半高+全高挡片 | E4: 02314GPV | F4: =VLOOKUP(C4,[1]备料总表!$B:$I,8,0) -> 99-001842 | G4: 是 | J4: 1 | K4: 替换 | L4: 1 | M4: 材料 | N4: 启用 | O4: 050210-00037 | P4: 050140-00028
A5: 69-001976 | B5: Atlas300V视频x16-24G-72W-SWHHHL半高+全高挡片 | C5: 302-002918 | D5: AI卡Atlas 300V-24G LPDDR4x-72W-HHHL | E5: 02314KDG | G5: 否 | J5: 1 | K5: 替换 | L5: 2 | M5: 材料 | N5: 启用 | O5: 050210-00037 | P5: 050140-00068
A6: 69-001976 | B6: Atlas300V视频x16-24G-72W-SWHHHL半高+全高挡片 | C6: 302-001842 | D6: AI卡Atlas 300V x16(HHHL)LDDR4*24GB | E6: 02314FUE | F6: =VLOOKUP(C6,[1]备料总表!$B:$I,8,0) -> 99-001842 | G6: 是 | J6: 1 | K6: 替换 | L6: 3 | M6: 材料 | N6: 启用 | O6: 050210-00037 | P6: 050140-00029
A8: 69-001558 | B8: FC HBA 16Gb-QLE2692 双口 | C8: 302-001010 | D8: FC HBA卡 16Gb-QLE2692-双口 | E8: QLE2692 | F8: =VLOOKUP(C8,[1]备料总表!$B:$I,8,0) -> 0 | J8: 1 | K8: 替换 | L8: 1 | M8: 材料 | N8: 启用 | O8: 050130-00071 | P8: 050220-00062
A10: 69-001594 | B10: 服务器8SAS+12NVME硬盘机箱-R522X | C10: 302-001688 | D10: 机箱 8SAS+12NVME硬盘 2U2P-无RAID SAS线1620S | E10: 02314CRG | F10: =VLOOKUP(C10,[1]备料总表!$B:$I,8,0) -> 88-000493 | J10: 1 | K10: 替换 | L10: 1 | M10: 材料 | N10: 启用 | O10: 050370-00031 | P10: 050370-00073
A11: 69-001594 | B11: 服务器8SAS+12NVME硬盘机箱-R522X | C11: 302-000018 | D11: 机箱 8SAS+12NVME硬盘 2U2P,K22R-02 1620S | E11: 02312YTF | F11: =VLOOKUP(C11,[1]备料总表!$B:$I,8,0) -> 88-000290 | J11: 1 | K11: 替换 | L11: 2 | M11: 材料 | N11: 启用 | O11: 050370-00031 | P11: 050370-00074
A13: 69-002177 | B13: 网卡SP670-2*100GE-SFP28-PCIe4.0x16-无模 | C13: 302-003374 | D13: 网卡SP670-2*100G-QSFP28-PCIe4.0x16-无模-无挡片 | E13: 02314UVY | F13: =VLOOKUP(C13,[1]备料总表!$B:$I,8,0) -> 99-003129 | J13: 1 | K13: 替换 | L13: 2 | M13: 材料 | N13: 启用 | O13: 050130-00161 | P13: 050130-00139
A14: 69-002177 | B14: 网卡SP670-2*100GE-SFP28-PCIe4.0x16-无模 | C14: 302-003129 | D14: 网卡-SP670-2*100G-QSFP28-pcie4.0x16-无模-无挡片 | E14: 02314CRT | F14: =VLOOKUP(C14,[1]备料总表!$B:$I,8,0) -> 99-003129 | J14: 1 | K14: 替换 | L14: 1 | M14: 材料 | N14: 启用 | O14: 050130-00161 | P14: 050130-00001
A15: 69-002177 | B15: 网卡SP670-2*100GE-SFP28-PCIe4.0x16-无模 | C15: 302-004724 | D15: 网卡SP670-2*100G-QSFP28-PCIe4.0x16无模FHFL | E15: #N/A | F15: =VLOOKUP(C15,[1]备料总表!$B:$I,8,0) -> #N/A | J15: 1 | K15: 替换 | L15: 3 | M15: 材料 | N15: 启用 | O15: 050130-00161 | P15: 050130-00230
A17: 69-001689 | B17: RAID扣卡 SR130(LSI3008)-no Cache | C17: 302-000690 | D17: RAID扣卡 SR130(LSI3008)-no Cache | E17: 02311UBX | F17: =VLOOKUP(C17,[1]备料总表!$B:$I,8,0) -> 99-000133 | J17: 1 | K17: 替换 | L17: 1 | M17: 材料 | N17: 启用 | O17: 050250-00033 | P17: 050250-00067
A19: 69-001958 | B19: 青松PC主板D2000 8C 2.3GHz-典配 | C19: 68-000107 | D19: 8核PC主板 D902L21K-2041K V4.0 BAREBONE | E19: #N/A | F19: =VLOOKUP(C19,[1]备料总表!$B:$I,8,0) -> #N/A | J19: 1 | K19: 替换 | L19: 1 | M19: 虚拟件 | N19: 启用 | O19: 050170-00007 | P19: 050170-00008
A20: 69-001958 | B20: 青松PC主板D2000 8C 2.3GHz-典配 | C20: 302-001061 | D20: 8核PC主板 D902L21K-2041K V2.0 | E20: 02313LUU | F20: =VLOOKUP(C20,[1]备料总表!$B:$I,8,0) -> 99-004063 | J20: 1 | K20: 替换 | L20: 2 | M20: 材料 | N20: 启用 | O20: 050170-00007 | P20: 050170-00171
A21: 69-001958 | B21: 青松PC主板D2000 8C 2.3GHz-典配 | C21: 302-001271 | D21: 8核PC主板 D902L21K-2041K V4.0 | E21: 02313RPS | F21: =VLOOKUP(C21,[1]备料总表!$B:$I,8,0) -> 99-004060 | J21: 1 | K21: 替换 | L21: 3 | M21: 材料 | N21: 启用 | O21: 050170-00007 | P21: 050170-00197
A23: 69-002433 | B23: NVMeSSD ES3500PV6&V7-3.84T-PCIe4-2.5读取 | C23: 302-003879 | D23: NVMeSSD ES3500PV6-3.84T-PCIe4-2.5读取HW1.3 | E23: 03034XEU | F23: =VLOOKUP(C23,[1]备料总表!$B:$I,8,0) -> 99-003404 | J23: 1 | K23: 替换 | M23: 材料 | N23: 启用 | O23: 050090-01791 | P23: 050090-01516
A24: 69-002433 | B24: NVMeSSD ES3500PV6&V7-3.84T-PCIe4-2.5读取 | C24: 302-004742 | D24: NVMeSSD ES3500P V7-3.84T-PCIe5 X4-2.5 HW | E24: #N/A | F24: =VLOOKUP(C24,[1]备料总表!$B:$I,8,0) -> #N/A | J24: 1 | K24: 替换 | M24: 材料 | N24: 启用 | O24: 050090-01791 | P24: 050090-01744
A25: 69-002433 | B25: NVMeSSD ES3500PV6&V7-3.84T-PCIe4-2.5读取 | C25: 302-004740 | D25: NVMeSSD ES3500P V7-3.84T-PCIe5 X4-2.5 HW | E25: #N/A | F25: =VLOOKUP(C25,[1]备料总表!$B:$I,8,0) -> #N/A | J25: 1 | K25: 替换 | M25: 材料 | N25: 启用 | O25: 050090-01791 | P25: 050090-01747
A27: 69-001750 | B27: 3.0G 服务器8*2.5直通机箱,不支持GPU-R822 | C27: 302-001138 | D27: 2U4P机箱8*2.5"直通3.0G 不支持GPU 支持BBU | E27: #N/A | F27: =VLOOKUP(C27,[1]备料总表!$B:$I,8,0) -> #N/A | J27: 1 | K27: 替换 | L27: 1 | M27: 材料 | N27: 启用 | O27: 050370-00123 | P27: 050370-00124
A29: 69-002239 | B29: 企业级固态盘 1.92T-SATA-2.5"-读取 AVAP | C29: 302-003251 | D29: SSD UM310a-1.92T-SATA-2.5 读取YL-[AVAP] | E29: RS2011T9MF003LX | F29: =VLOOKUP(C29,[1]备料总表!$B:$I,8,0) -> 99-003528 | J29: 1 | K29: 替换 | L29: 1 | M29: 材料 | N29: 启用 | O29: 050090-01337 | P29: 050090-00128
A30: 69-002239 | B30: 企业级固态盘 1.92T-SATA-2.5"-读取 AVAP | C30: 302-003647 | D30: SSD DTS510S20-1.92T-SATA-2.5-读取 DT AVAP | E30: J01T9SBLYAC8CDED90 | F30: =VLOOKUP(C30,[1]备料总表!$B:$I,8,0) -> 99-003647 | J30: 1 | K30: 替换 | L30: 2 | M30: 材料 | N30: 启用 | O30: 050090-01337 | P30: 050090-01411
A31: 69-002239 | B31: 企业级固态盘 1.92T-SATA-2.5"-读取 AVAP | C31: 302-003528 | D31: SSD 1.92T-SATA 6Gb-2.5-读取HLW AVAP | E31: F01T9T-EN00C3-M | F31: =VLOOKUP(C31,[1]备料总表!$B:$I,8,0) -> 99-003528 | J31: 1 | K31: 替换 | L31: 3 | M31: 材料 | N31: 启用 | O31: 050090-01337 | P31: 050090-01361
A32: 69-002239 | B32: 企业级固态盘 1.92T-SATA-2.5"-读取 AVAP | C32: 302-003952 | D32: SSD D300Y-1.92T-SATA 2.5 读取 HK-[AVAP] | E32: D03dBB8AA1920GC00 | F32: =VLOOKUP(C32,[1]备料总表!$B:$I,8,0) -> 99-003647 | J32: 1 | K32: 替换 | L32: 5 | M32: 材料 | N32: 启用 | O32: 050090-01337 | P32: 050090-01538
A33: 69-002239 | B33: 企业级固态盘 1.92T-SATA-2.5"-读取 AVAP | C33: 302-003552 | D33: SSD DSS200-B K5-1.92T-SATA2.5读取DT-[AVAP] | E33: 无-10 | F33: =VLOOKUP(C33,[1]备料总表!$B:$I,8,0) -> 99-003647 | J33: 1 | K33: 替换 | L33: 5 | M33: 材料 | N33: 启用 | O33: 050090-01337 | P33: 050090-01392
E34: #N/A | F34: =VLOOKUP(C34,[1]备料总表!$B:$I,8,0) -> #N/A | P34: 050370-00052
A35: 69-001751 | B35: S机箱2U4P-25*2.5SATA/SAS-EXP R822 | C35: 302-001137 | D35: 2U4P机箱25*2.5"EXP K24R-02 支持3.0G | E35: 02313PNJ | F35: =VLOOKUP(C35,[1]备料总表!$B:$I,8,0) -> 88-001775 | J35: 1 | K35: 替换 | L35: 2 | M35: 材料 | N35: 启用 | O35: 050370-00052 | P35: 050370-00125
A36: 69-001751 | B36: S机箱2U4P-25*2.5SATA/SAS-EXP R822 | C36: 302-003570 | D36: 服务器25*2.5英寸硬盘EXP 2U 3.0G标准机箱-R822 | E36: 02314RJS | F36: =VLOOKUP(C36,[1]备料总表!$B:$I,8,0) -> 雷哥确认bom | J36: 1 | K36: 替换 | L36: 1 | M36: 材料 | N36: 启用 | O36: 050370-00052 | P36: 050370-00273
E37: #N/A | F37: =VLOOKUP(C37,[1]备料总表!$B:$I,8,0) -> #N/A | P37: 050250-00001
A38: 69-001692 | B38: RAID扣卡SR150-M(Avago3408) | C38: 302-000133 | D38: RAID扣卡 SR150-M(Avago3408) | E38: 03033FAT | F38: =VLOOKUP(C38,[1]备料总表!$B:$I,8,0) -> 99-000133 | J38: 1 | K38: 替换 | L38: 1 | M38: 材料 | N38: 启用 | O38: 050250-00001 | P38: 050250-00030
A39: 69-001692 | B39: RAID扣卡SR150-M(Avago3408) | C39: 302-002308 | D39: RAID扣卡 SR150-M(Avago3408)V1.1 | E39: #N/A | F39: =VLOOKUP(C39,[1]备料总表!$B:$I,8,0) -> #N/A | J39: 1 | K39: 替换 | L39: 2 | M39: 材料 | N39: 启用 | O39: 050250-00001 | P39: 050250-00004
E40: #N/A | F40: =VLOOKUP(C40,[1]备料总表!$B:$I,8,0) -> #N/A | P40: 050210-00037
A41: 69-002069 | B41: S920X10-7262C 2* (鲲鹏920,64C@2.6,16DIMM) | C41: 302-002640 | D41: S主板 S920X10-2*7262C（64C@2.6）-AD | E41: 03050LSG | F41: =VLOOKUP(C41,[1]备料总表!$B:$I,8,0) -> 0 | J41: 1 | K41: 替换 | L41: 1 | M41: 材料 | N41: 启用 | O41: 050170-00229 | P41: 050170-00217
E42: #N/A | F42: =VLOOKUP(C42,[1]备料总表!$B:$I,8,0) -> #N/A | P42: 050370-00055
A43: 69-001796 | B43: 机箱 10*2.5支持10SAS(4NVMe)-直通-7260 R721 | C43: 302-001374 | D43: 1U2P机箱 10*2.5支持10SAS(4NVMe)-直通-7260 | E43: #N/A | F43: =VLOOKUP(C43,[1]备料总表!$B:$I,8,0) -> #N/A | J43: 1 | K43: 替换 | L43: 1 | M43: 材料 | N43: 启用 | O43: 050370-00055 | P43: 050370-00133
E44: #N/A | F44: =VLOOKUP(C44,[1]备料总表!$B:$I,8,0) -> #N/A | P44: 050090-00340
A45: 69-001932 | B45: 硬盘1.8T-SAS 12Gb/s-10K-2.5寸 XC | C45: 302-001039 | D45: S硬盘1.8T-2.5SAS-12G10K-128M-DZ V1.0 | E45: AL15SEB18EQ | F45: =VLOOKUP(C45,[1]备料总表!$B:$I,8,0) -> 99-001039 | J45: 1 | K45: 替换 | L45: 1 | M45: 材料 | N45: 启用 | O45: 050090-00340 | P45: 050090-00192
E46: #N/A | F46: =VLOOKUP(C46,[1]备料总表!$B:$I,8,0) -> #N/A | P46: 050090-00025
A47: 69-002075 | B47: 服务器12*3.5英寸EXP硬盘机箱-X10 | C47: 302-002160 | D47: 天池机箱2U2P-12*3.5EXP-X10（不含SAS线） | E47: 02314GUU | F47: =VLOOKUP(C47,[1]备料总表!$B:$I,8,0) -> 88-002689 | J47: 1 | K47: 替换 | L47: 1 | M47: 材料 | N47: 启用 | O47: 050090-00025 | P47: 050370-00223
E48: #N/A | F48: =VLOOKUP(C48,[1]备料总表!$B:$I,8,0) -> #N/A | P48: 050130-00042
...

Sheet “寻找替代料“批量导入查询
A1: 需求人导入表，支持批量导入查询，支持查询框单输入查询，支持导出，删除等
A2: 我导入 | B2: 我导入 | C2: 我导入 | D2: 系统自动输出疑似可替代物料信息 | E2: 系统输出 | F2: 系统输出 | G2: 系统输出
A3: 物料代码 | B3: 物料描述 | C3: 供应商PN码 | D3: 逻辑：①根据物料代码，找出根节点SAP.No“69-001511”，再关联出捆绑料号99-001049。 ①不行，则执行②，根据物料代码，先在自己PLM替代表里检索，PLM表检索查不到，再到“工厂物料清单”找，按供应商PN码查询，比如供应商PN码第一位没0，补齐0，有0则无需补,后缀-*也找出来，再到测算系统-物料工厂清单中精准找出供应商PN码一样的，物料代码显示出来 ③根据物料代码，先在自己PLM替代表里检索，PLM表检索查不到，再到“工厂物料清单”找按“子节点中文描述”或者供应商pn，模糊搜索相识度达90%及以上的，找出相识疑似可替代料物料信息 | E3: 疑似可替物料代码 | F3: 疑似可替子节点中文描述 | G3: 疑似可替供应商PN码
A4: 302-004695 | B4: S硬盘4T-3.5SATA-6G7.2K-256M-XJ-V1.0 | C4: NA-104 | E4: 99-001049 | F4: 取根节点的描述，硬盘4T-SATA 6Gb/s-7.2K-3.5无托 | G4: ①不显示，为空
A6: 302-004637 | B6: 制成板-BC83PRUIA-PCIe提升卡 IO1/IO2 1x8(Slot1) | C6: ‘0302025551 | E6: 302-001898 | F6: PCIe提升卡-IO1/IO2-3 x8三槽位 | G6: 302025551
A7: 302-004637 | B7: 制成板-BC83PRUIA-PCIe提升卡 IO1/IO2 1x8(Slot1) | C7: ‘0302025551 | E7: 302-00189* | G7: ’0302025551
A8: 302-004637 | B8: 制成板-BC83PRUIA-PCIe提升卡 IO1/IO2 1x8(Slot1) | C8: ‘0302025551 | E8: 302-0018** | G8: 302025551-1，-2
A10: 302-002937 | B10: SSD DTS510S00-960G-SATA 6Gb-2.5-读取 DT | C10: J960GSBLT3CACDED59 | E10: 302-002893 | F10: SSD DTS510S03-960GB-SATA 6Gb-2.5-读写 DT | G10: J960GSBLT3CCCDED80
A11: 302-004558 | B11: 网卡HP382-2*25G-PCIe3.0x8无模-?H?L | C11: 6310373 | D11: 根据物料代码，到PLM替代表查找，找不到，则到物料工厂清单找
A12: 302-004686 | B12: S主板S920X00-2*7260-64C@2.6G-CX-VD-1711 | C12: 03050SND

Sheet 替代料PLM系统导出逻辑
A1: PLM系统的替代关系表导出路径和方法

Sheet 仓库看板需求
A1: 一、 | B1: 核心指标层 | C1: 醒目数据快速展示
A2: 1 | B2: 库存资金总额 | C2: 当前武汉总库、各分库的备件成本 | D2: wms武汉总库移动平均价
A3: 4 | B3: 呆滞料占比 | C3: 近30天无出库记录且仍有库存的物料占比 | D3: 取物料号
A5: 二、 | B5: 库存结构分析
A6: 1 | B6: 备件ABC分类图 | C6: 按资金占比展示库存分布 | D6: A类高价值（10%数量占70%金额）、B类、C类低值易耗（根据需要设定阈值）
A7: 2 | B7: 品类分部树图 | C7: 直观展示各配件品类在库数量、金额 | D7: 一二三级品类
A9: 三、 | B9: 流动性、效率分析层
A10: 1 | B10: 出入库趋势图 | C10: 折线图对比近期收发量
A11: 2 | B11: 备件消耗排名 | C11: 按一二三级分类列出TOP10消耗件
A13: 四 | B13: 各库库间单运输时效 | C13: 取值tms时效 | D13: 抓去妥投状态，妥投超24H未过账，短信提醒货系统标红提示
A15: 五 | B15: 各库房出入库节点 | C15: 入库任务创建后未过账超72h标红提示； 出库待调度数量、待复核数量 | D15: 形成列表通知刘霞推动各库房整改
