Workbook

Sheet 说明
A1: 项目 | B1: CRM立项编号：SH250112118 项目名称：中国银联2025年智能算力服务器及网络设备采购项目（包1）
A2: 表1-1 备货配置BOM | B2: 获取报价单的配置BOM
A3: 表1-2 备货物料汇总 | B3: 根据表1-1，由物料号透视汇总数量
A4: 表2-1 销售订单明细 | B4: 即BI销售订单明细 | D4: 从vm_dcn_xsmx，按CRM立项编号抓取
A5: 表2-2 销售订单明细物料汇总 | B5: 根据表2-1，由物料号透视汇总数量
A6: 表2-3 产品BOM | B6: 查询SAP物料BOM，结合表2-2的产成品数量，将产成品按照BOM结构展开 | D6: 从material_find_manage，按物料号抓
A7: 表2-4 销售物料汇总 | B7: 根据表2-3，由物料号透视汇总数量
A8: 表3-1 备货-销售差异汇总 | B8: 结合表1-2、表2-4，对比差异
B10: 1、以项目的维度在页面展示（只抓取1-1和2-1都有的项目） 2、点击某个项目进行差异表计算（实时计算） 3、导出做一下数量限制，具体以查询速度定

Sheet 表1-1 备货配置BOM
A1: 物料类别 | B1: 产品名称 | C1: 料号 | D1: 描述 | E1: 单套数量 | F1: 总数量 | G1: 采购类型 | H1: 是否指定物料 | I1: 特殊说明
A2: 1 | B2: 305-000160 | C2: A924 DS | F2: 36
A3: 基础物料 | B3: 整机 | C3: 304000492 | D3: A924A2典配L6-4*920 2.6G 8*910_4_1 2Nvme 64G | E3: 1 | F3: 36 | G3: 华为采 | H3: 不指定物料
A4: 基础物料 | C4: 68000310 | D4: 02315HQP-70B_48C@2.6GHz_DS一体机底座 | E4: 1 | F4: 36 | G4: 外采 | H4: 不指定物料
A5: 基础物料 | B5: 内存 | C5: 302001644 | D5: S内存DDR4-32G-3200-2Rx4-RD HLS V1.0 | E5: 32 | F5: 1152 | G5: 华为采 | H5: 不指定物料
A6: 基础物料 | B6: 硬盘 | C6: 302002092 | D6: SSD ES3521AV6-960G-SATA-2.5读取HW+2.5托 侧孔 | E6: 2 | F6: 72 | G6: 外采 | H6: 不指定物料
A7: 基础物料 | B7: 硬盘 | C7: 302001354 | D7: SSD ES3521AV6-1.92T-SATA-6G-2.5读取HW侧孔1.0 | E7: 2 | F7: 72 | G7: 华为采 | H7: 不指定物料
A8: 基础物料 | B8: RAID卡 | C8: 302002612 | D8: RAID标卡9560-8i-4G PCIe4.0x8 NMP-HW | E8: 1 | F8: 36 | G8: 外采 | H8: 不指定物料
A9: 基础物料 | B9: 光模块和线缆 | C9: 302001844 | D9: SAS线-RAID卡专用1分2 mini SAS-1.0m&0.9m | E9: 1 | F9: 36 | G9: 华为采 | H9: 不指定物料
A10: 基础物料 | B10: RAID卡 | C10: 302001655 | D10: 3508/3516 RAID卡超级电容 | E10: 1 | F10: 36 | G10: 华为采 | H10: 不指定物料
A11: 基础物料 | B11: 网卡 | C11: 302003912 | D11: 灵活网卡2*200G接口卡-QSFP56 | E11: 4 | F11: 144 | G11: 华为采 | H11: 不指定物料
A12: 基础物料 | B12: 网卡 | C12: 302003302 | D12: 网卡HP382 25G双口SFP28(Mellanox CX-5) Lx无光模块-全高 | E12: 2 | F12: 72 | G12: 华为采 | H12: 不指定物料
A13: 基础物料 | B13: 光模块和线缆 | C13: 302003131 | D13: 光模块-SFP+-10G-多模(850nm,0.3km,LC)-HX | E13: 2 | F13: 72 | G13: 华为采 | H13: 不指定物料
A14: 基础物料 | B14: 光模块和线缆 | C14: 302003132 | D14: 光模块-SFP28-25G-多模(850nm,0.1km,LC)-HX | E14: 2 | F14: 72 | G14: 华为采 | H14: 不指定物料
A15: 基础物料 | B15: 昇腾 | C15: 302004291 | D15: 光模块-200G-QSFP56-多模-850nm-300m-TRC | E15: 8 | F15: 288 | G15: 华为采 | H15: 不指定物料
A16: 辅助料信息 | B16: 标签包装 | C16: 69001318 | D16: KunTai A924 服务器标准标签包装 | E16: 1 | F16: 36 | G16: 外采 | H16: 不指定物料
A17: 辅助料信息 | B17: BMC BIOS | C17: 68000324 | D17: A924推理典配BIOS/BMC固件包 | E17: 1 | F17: 36 | G17: 外采 | H17: 不指定物料
A18: 2 | B18: 305-000160 | C18: A924 DS | F18: 9
A19: 基础物料 | B19: 整机 | C19: 304000492 | D19: A924A2典配L6-4*920 2.6G 8*910_4_1 2Nvme 64G | E19: 1 | F19: 9 | G19: 华为采 | H19: 不指定物料
A20: 基础物料 | C20: 68000310 | D20: 02315HQP-70B_48C@2.6GHz_DS一体机底座 | E20: 1 | F20: 9 | G20: 外采 | H20: 不指定物料
A21: 基础物料 | B21: 内存 | C21: 302001644 | D21: S内存DDR4-32G-3200-2Rx4-RD HLS V1.0 | E21: 32 | F21: 288 | G21: 华为采 | H21: 不指定物料
A22: 基础物料 | B22: 硬盘 | C22: 302002092 | D22: SSD ES3521AV6-960G-SATA-2.5读取HW+2.5托 侧孔 | E22: 2 | F22: 18 | G22: 外采 | H22: 不指定物料
A23: 基础物料 | B23: 硬盘 | C23: 302001354 | D23: SSD ES3521AV6-1.92T-SATA-6G-2.5读取HW侧孔1.0 | E23: 2 | F23: 18 | G23: 华为采 | H23: 不指定物料
A24: 基础物料 | B24: RAID卡 | C24: 302002612 | D24: RAID标卡9560-8i-4G PCIe4.0x8 NMP-HW | E24: 1 | F24: 9 | G24: 外采 | H24: 不指定物料
A25: 基础物料 | B25: 光模块和线缆 | C25: 302001844 | D25: SAS线-RAID卡专用1分2 mini SAS-1.0m&0.9m | E25: 1 | F25: 9 | G25: 华为采 | H25: 不指定物料
A26: 基础物料 | B26: RAID卡 | C26: 302001655 | D26: 3508/3516 RAID卡超级电容 | E26: 1 | F26: 9 | G26: 华为采 | H26: 不指定物料
A27: 基础物料 | B27: 网卡 | C27: 302003912 | D27: 灵活网卡2*200G接口卡-QSFP56 | E27: 4 | F27: 36 | G27: 华为采 | H27: 不指定物料
A28: 基础物料 | B28: 网卡 | C28: 302003302 | D28: 网卡HP382 25G双口SFP28(Mellanox CX-5) Lx无光模块-全高 | E28: 2 | F28: 18 | G28: 华为采 | H28: 不指定物料
A29: 基础物料 | B29: 光模块和线缆 | C29: 302003131 | D29: 光模块-SFP+-10G-多模(850nm,0.3km,LC)-HX | E29: 2 | F29: 18 | G29: 华为采 | H29: 不指定物料
A30: 基础物料 | B30: 光模块和线缆 | C30: 302003132 | D30: 光模块-SFP28-25G-多模(850nm,0.1km,LC)-HX | E30: 2 | F30: 18 | G30: 华为采 | H30: 不指定物料
A31: 基础物料 | B31: 昇腾 | C31: 302004291 | D31: 光模块-200G-QSFP56-多模-850nm-300m-TRC | E31: 8 | F31: 72 | G31: 华为采 | H31: 不指定物料
A32: 辅助料信息 | B32: 标签包装 | C32: 69001318 | D32: KunTai A924 服务器标准标签包装 | E32: 1 | F32: 9 | G32: 外采 | H32: 不指定物料
A33: 辅助料信息 | B33: BMC BIOS | C33: 68000324 | D33: A924推理典配BIOS/BMC固件包 | E33: 1 | F33: 9 | G33: 外采 | H33: 不指定物料
A34: 3 | B34: 305-000029 | C34: R722 | F34: 628
A35: 基础物料 | B35: 机箱 | C35: 302003095 | D35: 机箱2U2P-12*3.5EXP-S920S00 | E35: 1 | F35: 628 | G35: 华为采 | H35: 不指定物料
A36: 基础物料 | B36: 主板 | C36: 302001363 | D36: S主板S920S00-2*5220(32C@2.6)-AJ-VE-1711 | E36: 1 | F36: 628 | G36: 华为采 | H36: 不指定物料
A37: 基础物料 | B37: 内存 | C37: 302001644 | D37: S内存DDR4-32G-3200-2Rx4-RD HLS V1.0 | E37: 12 | F37: 7536 | G37: 华为采 | H37: 不指定物料
A38: 基础物料 | B38: RISER卡 | C38: 302000147 | D38: 3*16X SLOT (PCIE X8) Riser1&2 模组 | E38: 2 | F38: 1256 | G38: 华为采 | H38: 不指定物料
A39: 基础物料 | B39: 硬盘 | C39: 302001040 | D39: S硬盘1.2T-2.5SAS-12G10K-128M-DZ V1.1 | E39: 2 | F39: 1256 | G39: 华为采 | H39: 不指定物料
A40: 基础物料 | B40: 硬盘 | C40: 302001354 | D40: SSD ES3521AV6-1.92T-SATA-6G-2.5读取HW侧孔1.0 | E40: 6 | F40: 3768 | G40: 华为采 | H40: 不指定物料
...

Sheet 表1-2 备货物料汇总
A3: 行标签 | B3: 求和项:总数量
A4: A924 DS | B4: 45
A5: R722 | B5: 628
A6: 304000492 | B6: 45
A7: 68000310 | B7: 45
A8: 302001644 | B8: 8976
A9: 302002092 | B9: 90
A10: 302001354 | B10: 3858
A11: 302002612 | B11: 45
A12: 302001844 | B12: 45
A13: 302001655 | B13: 673
A14: 302003912 | B14: 180
A15: 302003302 | B15: 90
A16: 302003131 | B16: 1346
A17: 302003132 | B17: 1346
... A36: 80008592 | B36: 628
A37: 总计 | B37: 31678

Sheet 表2-1 销售订单明细
A1: 销售订单号 | B1: 销售订单行项目 | C1: 交货单号 | D1: 交货单行项目 | E1: 物料代码 | F1: 物料名称 | G1: 数量
A2: 0015844780 | B2: 000030 | C2: 0015844780 | D2: 000030 | E2: 000000000082000002 | F2: 价外费用 | G2: 1
A3: 0015844779 | B3: 000040 | C3: 0814967635 | D3: 000040 | E3: 000000000306010455 | F3: KunTai R722 服务器 | G3: 212
A4: 0015844780 | B4: 000020 | C4: 0015844780 | D4: 000020 | E4: 000000000082000002 | F4: 价外费用 | G4: 1
A5: 0015844779 | B5: 000010 | C5: 0814967635 | D5: 000010 | E5: 000000000306010454 | F5: KunTai A924 DS 服务器 | G5: 36
A6: 0015844779 | B6: 000020 | C6: 0814967635 | D6: 000020 | E6: 000000000306010453 | F6: KunTai A924 DS 服务器 | G6: 9
A7: 0015844779 | B7: 000030 | C7: 0814967635 | D7: 000030 | E7: 000000000306010452 | F7: KunTai R722 服务器 | G7: 21
A8: 0015844779 | B8: 000050 | C8: 0814967635 | D8: 000050 | E8: 000000000306010451 | F8: KunTai R722 服务器 | G8: 81
A9: 0015844780 | B9: 000010 | C9: 0814967636 | D9: 000010 | E9: 000000000306010452 | F9: KunTai R722 服务器 | G9: 314

Sheet 表2-2 销售订单明细物料汇总
A3: 行标签 | B3: 求和项:数量
A4: 000000000082000002 | B4: 2
A5: 000000000306010451 | B5: 81
A6: 000000000306010452 | B6: 335
A7: 000000000306010453 | B7: 9
A8: 000000000306010454 | B8: 36
A9: 000000000306010455 | B9: 212
A10: 总计 | B10: 675

Sheet 表2-3 产品BOM
A1: 物料代码 | B1: 物料名称 | C1: 工厂代码 | D1: 项目类别 | E1: BOM项目号 | F1: BOM组件代码 | G1: BOM组件名称 | H1: 组件数量 | I1: 总数量
A2: 1 | H2: 212
A3: 306010455 | B3: KunTai R722 服务器 | C3: MTMU | D3: L | E3: 20 | F3: 302001363 | G3: S主板S920S00-2*5220(32C@2.6)-AJ-VE-1711 | H3: 1 | I3: =H3*$H$2 -> 212
A4: 306010455 | B4: KunTai R722 服务器 | C4: MTMU | D4: N | E4: 10 | F4: 68000338 | G4: S机箱-12*3.5SATA/SAS-EXP R522散件 | H4: 1 | I4: =H4*$H$2 -> 212
A5: 306010455 | B5: KunTai R722 服务器 | C5: MTMU | D5: N | E5: 40 | F5: 68000179 | G5: 3*16X SLOT (PCIe X8)RISER1/2 | H5: 2 | I5: =H5*$H$2 -> 424
A6: 306010455 | B6: KunTai R722 服务器 | C6: MTMU | D6: L | E6: 30 | F6: 302004338 | G6: S内存DDR4-32G-3200-2Rx8-HLS | H6: 12 | I6: =H6*$H$2 -> 2544
A7: 306010455 | B7: KunTai R722 服务器 | C7: MTMU | D7: L | E7: 60 | F7: 302000315 | G7: Raid卡电池盒-21203767-001_draen.prt | H7: 1 | I7: =H7*$H$2 -> 212
A8: 306010455 | B8: KunTai R722 服务器 | C8: MTMU | D8: L | E8: 50 | F8: 302003586 | G8: 3508/3516 RAID卡超级电容(不含电池盒) | H8: 1 | I8: =H8*$H$2 -> 212
A9: 306010455 | B9: KunTai R722 服务器 | C9: MTMU | D9: L | E9: 80 | F9: 302003536 | G9: SSD ES3521AV6-1.92T-SATA-6G-2.5读取HW 侧底孔 | H9: 6 | I9: =H9*$H$2 -> 1272
A10: 306010455 | B10: KunTai R722 服务器 | C10: MTMU | D10: L | E10: 70 | F10: 302000631 | G10: S硬盘1.2T-2.5SAS-12G10K-128M-XJ V1.0 | H10: 2 | I10: =H10*$H$2 -> 424
A11: 306010455 | B11: KunTai R722 服务器 | C11: MTMU | D11: L | E11: 100 | F11: 302000251 | G11: 高速电缆 Mini SAS HD Cable-0.85m | H11: 2 | I11: =H11*$H$2 -> 424
A12: 306010455 | B12: KunTai R722 服务器 | C12: MTMU | D12: L | E12: 90 | F12: 302001164 | G12: RAID标卡9460-8i-2G-PCIe3.0x8 Cache | H12: 1 | I12: =H12*$H$2 -> 212
A13: 306010455 | B13: KunTai R722 服务器 | C13: MTMU | D13: L | E13: 120 | F13: 302000788 | G13: 网卡 MCX4121A-ACUT 2*25G SFP28-无模 | H13: 2 | I13: =H13*$H$2 -> 424
A14: 306010455 | B14: KunTai R722 服务器 | C14: MTMU | D14: L | E14: 110 | F14: 302001873 | G14: TM210板载灵活网卡4*1GE-RJ45 | H14: 1 | I14: =H14*$H$2 -> 212
... A25: 306010455 | B25: KunTai R722 服务器 | C25: MTMU | D25: L | E25: 230 | F25: 302000331 | G25: PCIe全高挡片-钣金-21122419 | H25: 3 | I25: =H25*$H$2 -> 636
A26: 2 | H26: 36
A27: 306010454 | B27: KunTai A924 DS 服务器 | C27: MTMU | D27: N | E27: 190 | F27: 68000028 | G27: 神码客制化2.5英寸硬盘托架组合 | H27: 4 | I27: =H27*$H$26 -> 144
A28: 306010454 | B28: KunTai A924 DS 服务器 | C28: MTMU | D28: N | E28: 180 | F28: 68000324 | G28: A924推理典配BIOS/BMC固件包 | H28: 1 | I28: =H28*$H$26 -> 36
A29: 306010454 | B29: KunTai A924 DS 服务器 | C29: MTMU | D29: L | E29: 200 | F29: 302000867 | G29: M.2 螺钉 M3*4 渡彩锌 | H29: 2 | I29: =H29*$H$26 -> 72
A30: 306010454 | B30: KunTai A924 DS 服务器 | C30: MTMU | D30: L | E30: 10 | F30: 304000492 | G30: A924典配L6-4*920 2.6G 8*910_4_1 2Nvme 64G | H30: 1 | I30: =H30*$H$26 -> 36
A31: 306010454 | B31: KunTai A924 DS 服务器 | C31: MTMU | D31: L | E31: 30 | F31: 302004338 | G31: S内存DDR4-32G-3200-2Rx8-HLS | H31: 32 | I31: =H31*$H$26 -> 1152
A32: 306010454 | B32: KunTai A924 DS 服务器 | C32: MTMU | D32: N | E32: 20 | F32: 68000310 | G32: 02315HQP-70B_48C@2.6GHz_DS一体机底座 | H32: 1 | I32: =H32*$H$26 -> 36
A33: 306010454 | B33: KunTai A924 DS 服务器 | C33: MTMU | D33: L | E33: 50 | F33: 302004227 | G33: SSD ES3521A V7-1.92T-SATA-2.5-读取 HW V1.0 | H33: 2 | I33: =H33*$H$26 -> 72
A34: 306010454 | B34: KunTai A924 DS 服务器 | C34: MTMU | D34: L | E34: 40 | F34: 302001349 | G34: SSD ES3521AV6-960G-SATA-6G-2.5读取HW侧孔1.0 | H34: 2 | I34: =H34*$H$26 -> 72
A35: 306010454 | B35: KunTai A924 DS 服务器 | C35: MTMU | D35: L | E35: 70 | F35: 302002612 | G35: RAID标卡9560-8i-4G-PCIe4.0x8 HW NMP | H35: 1 | I35: =H35*$H$26 -> 36
A36: 306010454 | B36: KunTai A924 DS 服务器 | C36: MTMU | D36: L | E36: 60 | F36: 302001844 | G36: SAS线-Mini SAS to 2*Mini SAS-1.0m&0.9m HW | H36: 1 | I36: =H36*$H$26 -> 36
A37: 306010454 | B37: KunTai A924 DS 服务器 | C37: MTMU | D37: L | E37: 90 | F37: 302000315 | G37: Raid卡电池盒-21203767-001_draen.prt | H37: 1 | I37: =H37*$H$26 -> 36
A38: 306010454 | B38: KunTai A924 DS 服务器 | C38: MTMU | D38: L | E38: 80 | F38: 302003586 | G38: 3508/3516 RAID卡超级电容(不含电池盒) | H38: 1 | I38: =H38*$H$26 -> 36
... A46: 306010454 | B46: KunTai A924 DS 服务器 | C46: MTMU | D46: L | E46: 160 | F46: 302003171 | G46: 光模块-25G-SFP28-多模-850nm-0.3km-LC-TRC | H46: 2 | I46: =H46*$H$26 -> 72
A47: 3 | H47: 9
A48: 306010453 | B48: KunTai A924 DS 服务器 | C48: MTMU | D48: L | E48: 10 | F48: 304000492 | G48: A924典配L6-4*920 2.6G 8*910_4_1 2Nvme 64G | H48: 1 | I48: =H48*$H$47 -> 9
A49: 306010453 | B49: KunTai A924 DS 服务器 | C49: MTMU | D49: L | E49: 30 | F49: 302004338 | G49: S内存DDR4-32G-3200-2Rx8-HLS | H49: 32 | I49: =H49*$H$47 -> 288
A50: 306010453 | B50: KunTai A924 DS 服务器 | C50: MTMU | D50: N | E50: 20 | F50: 68000310 | G50: 02315HQP-70B_48C@2.6GHz_DS一体机底座 | H50: 1 | I50: =H50*$H$47 -> 9
A51: 306010453 | B51: KunTai A924 DS 服务器 | C51: MTMU | D51: L | E51: 50 | F51: 302004227 | G51: SSD ES3521A V7-1.92T-SATA-2.5-读取 HW V1.0 | H51: 2 | I51: =H51*$H$47 -> 18
A52: 306010453 | B52: KunTai A924 DS 服务器 | C52: MTMU | D52: L | E52: 40 | F52: 302001349 | G52: SSD ES3521AV6-960G-SATA-6G-2.5读取HW侧孔1.0 | H52: 2 | I52: =H52*$H$47 -> 18
A53: 306010453 | B53: KunTai A924 DS 服务器 | C53: MTMU | D53: L | E53: 70 | F53: 302001844 | G53: SAS线-Mini SAS to 2*Mini SAS-1.0m&0.9m HW | H53: 1 | I53: =H53*$H$47 -> 9
A54: 306010453 | B54: KunTai A924 DS 服务器 | C54: MTMU | D54: L | E54: 60 | F54: 302002612 | G54: RAID标卡9560-8i-4G-PCIe4.0x8 HW NMP | H54: 1 | I54: =H54*$H$47 -> 9
A55: 306010453 | B55: KunTai A924 DS 服务器 | C55: MTMU | D55: L | E55: 90 | F55: 302000315 | G55: Raid卡电池盒-21203767-001_draen.prt | H55: 1 | I55: =H55*$H$47 -> 9
A56: 306010453 | B56: KunTai A924 DS 服务器 | C56: MTMU | D56: L | E56: 80 | F56: 302003586 | G56: 3508/3516 RAID卡超级电容(不含电池盒) | H56: 1 | I56: =H56*$H$47 -> 9
A57: 306010453 | B57: KunTai A924 DS 服务器 | C57: MTMU | D57: L | E57: 110 | F57: 302003810 | G57: 网卡HP382 2*25G-SFP28-PCIE 3.0 x8-无挡片 | H57: 1 | I57: =H57*$H$47 -> 9
...

Sheet 表2-4 销售物料汇总
A3: 行标签 | B3: 求和项:总数量
A4: 68000027 | B4: 5024
A5: 68000028 | B5: 180
A6: 68000053 | B6: 628
A7: 68000179 | B7: 1256
A8: 68000310 | B8: 45
A9: 68000324 | B9: 45
A10: 68000338 | B10: 628
A11: 69001312 | B11: 628
A12: 69001318 | B12: 45
A13: 302000187 | B13: 628
A14: 302000248 | B14: 1256
A15: 302000251 | B15: 1256
... A43: 313000892 | B43: 628
A44: (空白)
A45: 总计 | B45: 40157

Sheet 表3-1 备货-销售差异汇总
A1: 物料代码 | B1: 物料名称 | C1: 备货总数量 | D1: 销售总数量 | E1: 差异(备货-销售)
A2: 68000027 | B2: =VLOOKUP(A2,'表2-3 产品BOM'!$F$3:$G$115,2,0) -> 2.5转3.5英寸硬盘托架组合 | C2: 0 | D2: =VLOOKUP(A2,'表2-4 销售物料汇总'!$A$4:$B$43,2,0) -> 5024 | E2: =C2-D2 -> -5024
A3: 68000028 | B3: =VLOOKUP(A3,'表2-3 产品BOM'!$F$3:$G$115,2,0) -> 神码客制化2.5英寸硬盘托架组合 | C3: 0 | D3: =VLOOKUP(A3,'表2-4 销售物料汇总'!$A$4:$B$43,2,0) -> 180 | E3: =C3-D3 -> -180
A4: 68000053 | B4: =VLOOKUP(A4,'表1-1 备货配置BOM'!$C$3:$D$55,2,0) -> S920S00？VE主板 BIOS 1711BMC CPLD | C4: =VLOOKUP(A4,'表1-2 备货物料汇总'!$A$4:$B$36,2,0) -> 628 | D4: =VLOOKUP(A4,'表2-4 销售物料汇总'!$A$4:$B$43,2,0) -> 628 | E4: =C4-D4 -> 0
A5: 68000179 | B5: =VLOOKUP(A5,'表2-3 产品BOM'!$F$3:$G$115,2,0) -> 3*16X SLOT (PCIe X8)RISER1/2 | C5: 0 | D5: =VLOOKUP(A5,'表2-4 销售物料汇总'!$A$4:$B$43,2,0) -> 1256 | E5: =C5-D5 -> -1256
A6: 68000310 | B6: =VLOOKUP(A6,'表1-1 备货配置BOM'!$C$3:$D$55,2,0) -> 02315HQP-70B_48C@2.6GHz_DS一体机底座 | C6: =VLOOKUP(A6,'表1-2 备货物料汇总'!$A$4:$B$36,2,0) -> 45 | D6: =VLOOKUP(A6,'表2-4 销售物料汇总'!$A$4:$B$43,2,0) -> 45 | E6: =C6-D6 -> 0
A7: 68000324 | B7: =VLOOKUP(A7,'表1-1 备货配置BOM'!$C$3:$D$55,2,0) -> A924推理典配BIOS/BMC固件包 | C7: =VLOOKUP(A7,'表1-2 备货物料汇总'!$A$4:$B$36,2,0) -> 45 | D7: =VLOOKUP(A7,'表2-4 销售物料汇总'!$A$4:$B$43,2,0) -> 45 | E7: =C7-D7 -> 0
A8: 68000338 | B8: =VLOOKUP(A8,'表2-3 产品BOM'!$F$3:$G$115,2,0) -> S机箱-12*3.5SATA/SAS-EXP R522散件 | C8: 0 | D8: =VLOOKUP(A8,'表2-4 销售物料汇总'!$A$4:$B$43,2,0) -> 628 | E8: =C8-D8 -> -628
A9: 69001312 | B9: =VLOOKUP(A9,'表1-1 备货配置BOM'!$C$3:$D$55,2,0) -> KunTai R722 服务器标准标签包装 | C9: =VLOOKUP(A9,'表1-2 备货物料汇总'!$A$4:$B$36,2,0) -> 628 | D9: =VLOOKUP(A9,'表2-4 销售物料汇总'!$A$4:$B$43,2,0) -> 628 | E9: =C9-D9 -> 0
A10: 69001318 | B10: =VLOOKUP(A10,'表1-1 备货配置BOM'!$C$3:$D$55,2,0) -> KunTai A924 服务器标准标签包装 | C10: =VLOOKUP(A10,'表1-2 备货物料汇总'!$A$4:$B$36,2,0) -> 45 | D10: =VLOOKUP(A10,'表2-4 销售物料汇总'!$A$4:$B$43,2,0) -> 45 | E10: =C10-D10 -> 0
A11: 80008592 | B11: =VLOOKUP(A11,'表1-1 备货配置BOM'!$C$3:$D$55,2,0) -> 鲲泰服务器基础硬件安装服务-2U | C11: =VLOOKUP(A11,'表1-2 备货物料汇总'!$A$4:$B$36,2,0) -> 628 | D11: 0 | E11: =C11-D11 -> 628
A12: 80008624 | B12: =VLOOKUP(A12,'表1-1 备货配置BOM'!$C$3:$D$55,2,0) -> 鲲泰服务器维保服务：金牌+服务包-2U-5年,7*24*4H | C12: =VLOOKUP(A12,'表1-2 备货物料汇总'!$A$4:$B$36,2,0) -> 628 | D12: 0 | E12: =C12-D12 -> 628
A13: 80008653 | B13: =VLOOKUP(A13,'表1-1 备货配置BOM'!$C$3:$D$55,2,0) -> 鲲泰服务器硬盘介质保留-2U-5年 | C13: =VLOOKUP(A13,'表1-2 备货物料汇总'!$A$4:$B$36,2,0) -> 628 | D13: 0 | E13: =C13-D13 -> 628
A14: 302000147 | B14: =VLOOKUP(A14,'表1-1 备货配置BOM'!$C$3:$D$55,2,0) -> 3*16X SLOT (PCIE X8) Riser1&2 模组 | C14: =VLOOKUP(A14,'表1-2 备货物料汇总'!$A$4:$B$36,2,0) -> 1256 | D14: 0 | E14: =C14-D14 -> 1256
A15: 302000187 | B15: =VLOOKUP(A15,'表1-1 备货配置BOM'!$C$3:$D$55,2,0) -> 2U静态滑轨套件 | C15: =VLOOKUP(A15,'表1-2 备货物料汇总'!$A$4:$B$36,2,0) -> 628 | D15: =VLOOKUP(A15,'表2-4 销售物料汇总'!$A$4:$B$43,2,0) -> 628 | E15: =C15-D15 -> 0
A16: 302000248 | B16: =VLOOKUP(A16,'表1-1 备货配置BOM'!$C$3:$D$55,2,0) -> S电源线PDU国标-C14直公-C13直母-250V10A-1.5m黑-交流 | C16: =VLOOKUP(A16,'表1-2 备货物料汇总'!$A$4:$B$36,2,0) -> 1256 | D16: =VLOOKUP(A16,'表2-4 销售物料汇总'!$A$4:$B$43,2,0) -> 1256 | E16: =C16-D16 -> 0
A17: 302000251 | B17: =VLOOKUP(A17,'表1-1 备货配置BOM'!$C$3:$D$55,2,0) -> 高速电缆 Mini SAS HCable-0.85m | C17: =VLOOKUP(A17,'表1-2 备货物料汇总'!$A$4:$B$36,2,0) -> 1256 | D17: =VLOOKUP(A17,'表2-4 销售物料汇总'!$A$4:$B$43,2,0) -> 1256 | E17: =C17-D17 -> 0
A18: 302000271 | B18: =VLOOKUP(A18,'表2-3 产品BOM'!$F$3:$G$115,2,0) -> 3.5英寸假硬盘托架 | C18: 0 | D18: =VLOOKUP(A18,'表2-4 销售物料汇总'!$A$4:$B$43,2,0) -> 2512 | E18: =C18-D18 -> -2512
A19: 302000315 | B19: =VLOOKUP(A19,'表2-3 产品BOM'!$F$3:$G$115,2,0) -> Raid卡电池盒-21203767-001_draen.prt | C19: 0 | D19: =VLOOKUP(A19,'表2-4 销售物料汇总'!$A$4:$B$43,2,0) -> 673 | E19: =C19-D19 -> -673
A20: 302000331 | B20: =VLOOKUP(A20,'表2-3 产品BOM'!$F$3:$G$115,2,0) -> PCIe全高挡片-钣金-21122419 | C20: 0 | D20: =VLOOKUP(A20,'表2-4 销售物料汇总'!$A$4:$B$43,2,0) -> 1884 | E20: =C20-D20 -> -1884
A21: 302000631 | B21: =VLOOKUP(A21,'表2-3 产品BOM'!$F$3:$G$115,2,0) -> S硬盘1.2T-2.5SAS-12G10K-128M-XJ V1.0 | C21: 0 | D21: =VLOOKUP(A21,'表2-4 销售物料汇总'!$A$4:$B$43,2,0) -> 1256 | E21: =C21-D21 -> -1256
A22: 302000788 | B22: =VLOOKUP(A22,'表1-1 备货配置BOM'!$C$3:$D$55,2,0) -> 网卡 MCX4121A-ACUT 25G双口SFP28 | C22: =VLOOKUP(A22,'表1-2 备货物料汇总'!$A$4:$B$36,2,0) -> 1256 | D22: =VLOOKUP(A22,'表2-4 销售物料汇总'!$A$4:$B$43,2,0) -> 1256 | E22: =C22-D22 -> 0
A23: 302000867 | B23: =VLOOKUP(A23,'表2-3 产品BOM'!$F$3:$G$115,2,0) -> M.2 螺钉 M3*4 渡彩锌 | C23: 0 | D23: =VLOOKUP(A23,'表2-4 销售物料汇总'!$A$4:$B$43,2,0) -> 90 | E23: =C23-D23 -> -90
A24: 302001040 | B24: =VLOOKUP(A24,'表1-1 备货配置BOM'!$C$3:$D$55,2,0) -> S硬盘1.2T-2.5SAS-12G10K-128M-DZ V1.1 | C24: =VLOOKUP(A24,'表1-2 备货物料汇总'!$A$4:$B$36,2,0) -> 1256 | D24: 0 | E24: =C24-D24 -> 1256
A25: 302001164 | B25: =VLOOKUP(A25,'表2-3 产品BOM'!$F$3:$G$115,2,0) -> RAID标卡9460-8i-2G-PCIe3.0x8 Cache | C25: 0 | D25: =VLOOKUP(A25,'表2-4 销售物料汇总'!$A$4:$B$43,2,0) -> 628 | E25: =C25-D25 -> -628
A26: 302001332 | B26: =VLOOKUP(A26,'表1-1 备货配置BOM'!$C$3:$D$55,2,0) -> RAID标卡-2GB 9460-8i-PCIe | C26: =VLOOKUP(A26,'表1-2 备货物料汇总'!$A$4:$B$36,2,0) -> 628 | D26: 0 | E26: =C26-D26 -> 628
A27: 302001349 | B27: =VLOOKUP(A27,'表2-3 产品BOM'!$F$3:$G$115,2,0) -> SSD ES3521AV6-960G-SATA-6G-2.5读取HW侧孔1.0 | C27: 0 | D27: =VLOOKUP(A27,'表2-4 销售物料汇总'!$A$4:$B$43,2,0) -> 90 | E27: =C27-D27 -> -90
A28: 302001354 | B28: =VLOOKUP(A28,'表1-1 备货配置BOM'!$C$3:$D$55,2,0) -> SSD ES3521AV6-1.92T-SATA-6G-2.5读取HW侧孔1.0 | C28: =VLOOKUP(A28,'表1-2 备货物料汇总'!$A$4:$B$36,2,0) -> 3858 | D28: 0 | E28: =C28-D28 -> 3858
A29: 302001363 | B29: =VLOOKUP(A29,'表1-1 备货配置BOM'!$C$3:$D$55,2,0) -> S主板S920S00-2*5220(32C@2.6)-AJ-VE-1711 | C29: =VLOOKUP(A29,'表1-2 备货物料汇总'!$A$4:$B$36,2,0) -> 628 | D29: =VLOOKUP(A29,'表2-4 销售物料汇总'!$A$4:$B$43,2,0) -> 628 | E29: =C29-D29 -> 0
A30: 302001644 | B30: =VLOOKUP(A30,'表1-1 备货配置BOM'!$C$3:$D$55,2,0) -> S内存DDR4-32G-3200-2Rx4-RD HLS V1.0 | C30: =VLOOKUP(A30,'表1-2 备货物料汇总'!$A$4:$B$36,2,0) -> 8976 | D30: 0 | E30: =C30-D30 -> 8976
A31: 302001655 | B31: =VLOOKUP(A31,'表1-1 备货配置BOM'!$C$3:$D$55,2,0) -> 3508/3516 RAID卡超级电容 | C31: =VLOOKUP(A31,'表1-2 备货物料汇总'!$A$4:$B$36,2,0) -> 673 | D31: 0 | E31: =C31-D31 -> 673
A32: 302001844 | B32: =VLOOKUP(A32,'表1-1 备货配置BOM'!$C$3:$D$55,2,0) -> SAS线-RAID卡专用1分2 mini SAS-1.0m&0.9m | C32: =VLOOKUP(A32,'表1-2 备货物料汇总'!$A$4:$B$36,2,0) -> 45 | D32: =VLOOKUP(A32,'表2-4 销售物料汇总'!$A$4:$B$43,2,0) -> 45 | E32: =C32-D32 -> 0
A33: 302001873 | B33: =VLOOKUP(A33,'表1-1 备货配置BOM'!$C$3:$D$55,2,0) -> TM210板载灵活网卡4*1GE-RJ45 | C33: =VLOOKUP(A33,'表1-2 备货物料汇总'!$A$4:$B$36,2,0) -> 628 | D33: =VLOOKUP(A33,'表2-4 销售物料汇总'!$A$4:$B$43,2,0) -> 628 | E33: =C33-D33 -> 0
A34: 302002092 | B34: =VLOOKUP(A34,'表1-1 备货配置BOM'!$C$3:$D$55,2,0) -> SSD ES3521AV6-960G-SATA-2.5读取HW+2.5托 侧孔 | C34: =VLOOKUP(A34,'表1-2 备货物料汇总'!$A$4:$B$36,2,0) -> 90 | D34: 0 | E34: =C34-D34 -> 90
A35: 302002612 | B35: =VLOOKUP(A35,'表1-1 备货配置BOM'!$C$3:$D$55,2,0) -> RAID标卡9560-8i-4G PCIe4.0x8 NMP-HW | C35: =VLOOKUP(A35,'表1-2 备货物料汇总'!$A$4:$B$36,2,0) -> 45 | D35: =VLOOKUP(A35,'表2-4 销售物料汇总'!$A$4:$B$43,2,0) -> 45 | E35: =C35-D35 -> 0
A36: 302003095 | B36: =VLOOKUP(A36,'表1-1 备货配置BOM'!$C$3:$D$55,2,0) -> 机箱2U2P-12*3.5EXP-S920S00 | C36: =VLOOKUP(A36,'表1-2 备货物料汇总'!$A$4:$B$36,2,0) -> 628 | D36: 0 | E36: =C36-D36 -> 628
A37: 302003131 | B37: =VLOOKUP(A37,'表1-1 备货配置BOM'!$C$3:$D$55,2,0) -> 光模块-SFP+-10G-多模(850nm,0.3km,LC)-HX | C37: =VLOOKUP(A37,'表1-2 备货物料汇总'!$A$4:$B$36,2,0) -> 1346 | D37: 0 | E37: =C37-D37 -> 1346
A38: 302003132 | B38: =VLOOKUP(A38,'表1-1 备货配置BOM'!$C$3:$D$55,2,0) -> 光模块-SFP28-25G-多模(850nm,0.1km,LC)-HX | C38: =VLOOKUP(A38,'表1-2 备货物料汇总'!$A$4:$B$36,2,0) -> 1346 | D38: 0 | E38: =C38-D38 -> 1346
A39: 302003171 | B39: =VLOOKUP(A39,'表2-3 产品BOM'!$F$3:$G$115,2,0) -> 光模块-25G-SFP28-多模-850nm-0.3km-LC-TRC | C39: 0 | D39: =VLOOKUP(A39,'表2-4 销售物料汇总'!$A$4:$B$43,2,0) -> 1346 | E39: =C39-D39 -> -1346
A40: 302003302 | B40: =VLOOKUP(A40,'表1-1 备货配置BOM'!$C$3:$D$55,2,0) -> 网卡HP382 25G双口SFP28(Mellanox CX-5) Lx无光模块-全高 | C40: =VLOOKUP(A40,'表1-2 备货物料汇总'!$A$4:$B$36,2,0) -> 90 | D40: 0 | E40: =C40-D40 -> 90
...
