Workbook

Sheet 需求1欠料调拨
A1: 新建模块：欠料调拨
A2: 物料代码 | B2: 捆绑料号 | C2: 物料描述 | D2: 名称 | E2: 欠料城市 | F2: 欠料数量 | G2: 调拨城市 | H2: 调拨城市库存 | I2: 服务时效 | J2: 销售数量 | K2: 武汉总库库存 | L2: 区域L1库 | M2: 区域一级库库存 | N2: 计划员备注
A3: 系统自动抓取，条件1只抓"备料总表"中,当物料代码=捆绑料号且销量>0且库存量=0的物料代码。条件2只抓替代料备料总表中的捆绑料号，销量>0且库存量=0的捆绑料号作为物料代码。 ②此字段也支持手动导入或手工创建 | B3: 根据A列条件1成立显示备料总表捆绑料号，条件2成立显示替代料备料总表的捆绑料号 | C3: 根据A列“物料代码”到对应模块中抓取“物料描述”，如A列是条件1则抓取备料总表的物料描述，如是条件2则抓取“捆绑料号”模块下的描述，如99-打头捆绑料号，描述则选取任一名称即可，如是88-打头则选取描述中不带“机箱”字样中的任一描述即可 | D3: 根据A列“物料代码”到对应模块中抓取“名称”，如A列是条件1则抓取备料总表的名称，如是条件2则抓取替代料备料总表的名称 | E3: 根据A列物料代码，等于备料总表或替代料备料总表的“城市”=欠料城市 ②此字段也支持手动导入或手工创建 | F3: 根据A列物料代码和E列城市来关联匹配“备料总表”或“替代料备料总表”的缺口等于欠料数量。含高时效缺口标红，ND缺口标黄色。条件1成立通过A列物料代码和E列城市抓取备料总表的“缺口”数量。条件2成立通过A列物料代码和E列城市抓取替代料备料总表的“缺口”数量 | G3: 根据E列欠料城市=WMS库房分配表中“库存地”，关联出“备选库”，调拨城市=备选库 | H3: 等于A列物料代码，当条件1成立，则抓取各库区库存中物料代码在调拨城市中的汇总库存数量。当条件2成立，则抓取各库区库存中捆绑料号在调拨城市中的汇总后库存数量 | I3: 用A列物料代码条件1成立，关联汇总看板，E列欠料城市=汇总看板“库存地点”，则做“服务时效”比对，比对逻辑同生产系统PO单服务时效一样，得出服务时效。 比对逻辑： | J3: 以B列捆绑料号+E列欠料城市汇总“汇总看板”总数量 | K3: 以B列捆绑料号为准，汇总各库区库存“武汉”总数量 | L3: WMS库房分配表中最尾新增一个“区域一级库”，手动导入维护区域一级库， | M3: 根据B列捆绑料号，抓取汇总对应区域L1库的库存数量 | N3: 支持手动或者导入输入备注
A4: ①302-000471 | B4: 302-000471 | C4: 电缆-SlimLine-Riser1_背板-R62X | D4: 线缆 | E4: 福州 | F4: -1 | G4: 厦门 | H4: 0 | I4: 2H/4H | J4: 35 | K4: 1
A5: 条件①"备料总表"中,物料代码=捆绑料号且销量>0且库存量=0的物料代码
A6: ②99-000413 | B6: 99-000413 | C6: S主板 S920X02-5250-AF 4*(920,48C)1711-3A | D6: 主板 | E6: 东莞 | F6: -1 | G6: 广州 | H6: 1 | I6: 2H/4H | J6: 1 | K6: 2
A7: 条件②替代料备料总表中的捆绑料号，销量>0且库存量=0的捆绑料号。 | E7: 武汉项目=武汉项目
A9: 条件1截图案例
H10: 服务时效比对逻辑 | I10: 时效包含如下任一 | J10: 优先级 | K10: 显示内容
I11: 7*24*2H | J11: 第一梯队 | K11: 2H/4H
I12: 7*24*4H
I13: 7*24*ND | J13: 第二梯队 | K13: ND
I14: 7x24x5CD
I15: 7*24*3CD
I16: 基础保修 | J16: 第三梯队 | K16: 基础保修
A43: 条件2截图案例

Sheet 需求2本地库存查询优化
A1: 导入日期 | B1: 料号 | C1: 描述 | D1: 备件类别 | E1: 备注 | F1: 库房 | G1: 数量 | H1: 捆绑料号 | I1: 补库单状态 | J1: 发料日期 | K1: 库房剩余数量 | L1: 缺口 | M1: 当前武汉库存 | N1: 原料号武汉库存 | O1: 推荐补料料号 | P1: 项目名 | Q1: CRM立项编号 | R1: 校验库房 | S1: 校验捆绑料号
A2: 45944 | B2: 302-000174 | C2: 光模块-SFP+-10G-多模(850nm,0.3km,LC) | D2: 光模块 | F2: 佛山 | G2: 1 | H2: 99-000381 | K2: 9 | L2: 5 | M2: 99 | N2: 3 | O2: 302-001797 | P2: 手动导入 | Q2: 手动导入 | R2: 根据P列项目名或Q列CRM立项编号和F列库房，关联BOM总表“项目名”或“CRM立项编号”和“库存地点”，数据能关联匹配ok，则显示“√”，否则显示“×”。 | S2: 根据H列捆绑料号和F列库房，关联BOM总表“捆绑料号”和“库存地点”，数据能关联匹配ok，则显示“√”，否则显示“×”。

Sheet 截止目前未发货2
A1: 料号 | B1: 捆绑 | C1: 描述 | D1: 备件类别 | E1: 库区 | F1: 欠料数量 | G1: 备注 | H1: 2025/9/30武汉库存 | I1: 备注
A2: 302-000145 | B2: =A2 -> 302-000145 | C2: =VLOOKUP(A2,[1]备料总表!$B:$I,2,0) -> 4*3.5"后置硬盘背板(Riser1+2)组件(SAS/SATA) | D2: =VLOOKUP(A2,[1]备料总表!$B:$I,4,0) -> 后置硬盘背板 | E2: 济南 | F2: 1 | G2: nd3，北京供应或武汉供应 | H2: =VLOOKUP(B2,[2]各库区库存!$A:$B,2,0) -> 302-000145
A3: 302-000154 | B3: =A3 -> 302-000154 | C3: =VLOOKUP(A3,[1]备料总表!$B:$I,2,0) -> Riser3模组 2*16X SLOT (PCIE X8)DMINI | D3: =VLOOKUP(A3,[1]备料总表!$B:$I,4,0) -> Riser模组 | E3: 广州 | F3: 1 | G3: nd1，厦门有1供应，十五所KJ185项目 | H3: =VLOOKUP(B3,[2]各库区库存!$A:$B,2,0) -> 302-000154
A4: 302-000159 | B4: =A4 -> 302-000159 | C4: =VLOOKUP(A4,[1]备料总表!$B:$I,2,0) -> 网卡4*10GE(Hi1822)-SFP+-PCIe3.0x8 | D4: =VLOOKUP(A4,[1]备料总表!$B:$I,4,0) -> 网卡 | E4: 广州 | F4: 1 | G4: nd1，厦门有1供应，十五所KJ185项目 | H4: =VLOOKUP(B4,[2]各库区库存!$A:$B,2,0) -> 302-000159
A5: 302-000224 | B5: =A5 -> 302-000224 | C5: =VLOOKUP(A5,[1]备料总表!$B:$I,2,0) -> SSD S4510-480G-SATA-6G-2.5读取YTL V1.0 | D5: =VLOOKUP(A5,[1]备料总表!$B:$I,4,0) -> 硬盘 | E5: 沈阳 | F5: 1 | G5: 沈阳有750硬盘3pcs可替。产品白文飞：第三方应用的兼容需求，必须华为云、腾讯云啥的，如果没有就同69下750可以替换.2025/1/21韩洋回复这就一台机器，基本不涉及云类的应用。 | H5: =VLOOKUP(B5,[2]各库区库存!$A:$B,2,0) -> 302-000224
A6: 302-000298 | B6: =A6 -> 302-000298 | C6: =VLOOKUP(A6,[1]备料总表!$B:$I,2,0) -> 内置2.5寸硬盘背板-BC82HBBA | D6: =VLOOKUP(A6,[1]备料总表!$B:$I,4,0) -> 后置硬盘背板 | E6: 海口 | F6: 1 | G6: nd44，广州有302-000346 2pcs上级组件 | H6: =VLOOKUP(B6,[2]各库区库存!$A:$B,2,0) -> 302-000298
A7: 302-000370 | B7: =A7 -> 302-000370 | C7: =VLOOKUP(A7,[1]备料总表!$B:$I,2,0) -> 后置PSU 4*2.5硬盘背板组件 | D7: =VLOOKUP(A7,[1]备料总表!$B:$I,4,0) -> 后置硬盘背板 | E7: 南京 | F7: 1 | G7: nd5，暂同合肥供应 | H7: =VLOOKUP(B7,[2]各库区库存!$A:$B,2,0) -> 302-000370
A8: 302-000471 | B8: =A8 -> 302-000471 | C8: =VLOOKUP(A8,[1]备料总表!$B:$I,2,0) -> 电缆-SlimLine-Riser1_背板-R62X | D8: =VLOOKUP(A8,[1]备料总表!$B:$I,4,0) -> 线缆 | E8: 乌鲁木齐 | F8: 1 | G8: 5 | H8: =VLOOKUP(B8,[2]各库区库存!$A:$B,2,0) -> 302-000471
A9: 302-000471 | B9: =A9 -> 302-000471 | C9: =VLOOKUP(A9,[1]备料总表!$B:$I,2,0) -> 电缆-SlimLine-Riser1_背板-R62X | D9: =VLOOKUP(A9,[1]备料总表!$B:$I,4,0) -> 线缆 | E9: 长春 | F9: 1 | G9: 36 | H9: =VLOOKUP(B9,[2]各库区库存!$A:$B,2,0) -> 302-000471
A10: 302-000471 | B10: =A10 -> 302-000471 | C10: =VLOOKUP(A10,[1]备料总表!$B:$I,2,0) -> 电缆-SlimLine-Riser1_背板-R62X | D10: =VLOOKUP(A10,[1]备料总表!$B:$I,4,0) -> 线缆 | E10: 杭州 | F10: 1 | G10: 55 | H10: =VLOOKUP(B10,[2]各库区库存!$A:$B,2,0) -> 302-000471
A11: 302-000471 | B11: =A11 -> 302-000471 | C11: =VLOOKUP(A11,[1]备料总表!$B:$I,2,0) -> 电缆-SlimLine-Riser1_背板-R62X | D11: =VLOOKUP(A11,[1]备料总表!$B:$I,4,0) -> 线缆 | E11: 上海 | F11: 1 | G11: 55 | H11: =VLOOKUP(B11,[2]各库区库存!$A:$B,2,0) -> 302-000471
A12: 302-000471 | B12: =A12 -> 302-000471 | C12: =VLOOKUP(A12,[1]备料总表!$B:$I,2,0) -> 电缆-SlimLine-Riser1_背板-R62X | D12: =VLOOKUP(A12,[1]备料总表!$B:$I,4,0) -> 线缆 | E12: 厦门 | F12: 1 | G12: 28 | H12: =VLOOKUP(B12,[2]各库区库存!$A:$B,2,0) -> 302-000471
A13: 302-000471 | B13: =A13 -> 302-000471 | C13: =VLOOKUP(A13,[1]备料总表!$B:$I,2,0) -> 电缆-SlimLine-Riser1_背板-R62X | D13: =VLOOKUP(A13,[1]备料总表!$B:$I,4,0) -> 线缆 | E13: 哈尔滨 | F13: 1 | G13: 40 | H13: =VLOOKUP(B13,[2]各库区库存!$A:$B,2,0) -> 302-000471
A14: 302-000471 | B14: =A14 -> 302-000471 | C14: =VLOOKUP(A14,[1]备料总表!$B:$I,2,0) -> 电缆-SlimLine-Riser1_背板-R62X | D14: =VLOOKUP(A14,[1]备料总表!$B:$I,4,0) -> 线缆 | E14: 成都 | F14: 1 | G14: 19 | H14: =VLOOKUP(B14,[2]各库区库存!$A:$B,2,0) -> 302-000471
A15: 302-000471 | B15: =A15 -> 302-000471 | C15: =VLOOKUP(A15,[1]备料总表!$B:$I,2,0) -> 电缆-SlimLine-Riser1_背板-R62X | D15: =VLOOKUP(A15,[1]备料总表!$B:$I,4,0) -> 线缆 | E15: 济南 | F15: 1 | G15: 1 | H15: =VLOOKUP(B15,[2]各库区库存!$A:$B,2,0) -> 302-000471
A16: 302-000471 | B16: =A16 -> 302-000471 | C16: =VLOOKUP(A16,[1]备料总表!$B:$I,2,0) -> 电缆-SlimLine-Riser1_背板-R62X | D16: =VLOOKUP(A16,[1]备料总表!$B:$I,4,0) -> 线缆 | E16: 西安 | F16: 1 | G16: 11 | H16: =VLOOKUP(B16,[2]各库区库存!$A:$B,2,0) -> 302-000471
A17: 302-000471 | B17: =A17 -> 302-000471 | C17: =VLOOKUP(A17,[1]备料总表!$B:$I,2,0) -> 电缆-SlimLine-Riser1_背板-R62X | D17: =VLOOKUP(A17,[1]备料总表!$B:$I,4,0) -> 线缆 | E17: 呼和浩特 | F17: 1 | G17: 4 | H17: =VLOOKUP(B17,[2]各库区库存!$A:$B,2,0) -> 302-000471
A18: 302-000471 | B18: =A18 -> 302-000471 | C18: =VLOOKUP(A18,[1]备料总表!$B:$I,2,0) -> 电缆-SlimLine-Riser1_背板-R62X | D18: =VLOOKUP(A18,[1]备料总表!$B:$I,4,0) -> 线缆 | E18: 福州 | F18: 1 | G18: 4H14,nd21 | H18: =VLOOKUP(B18,[2]各库区库存!$A:$B,2,0) -> 302-000471
A19: 302-000471 | B19: =A19 -> 302-000471 | C19: =VLOOKUP(A19,[1]备料总表!$B:$I,2,0) -> 电缆-SlimLine-Riser1_背板-R62X | D19: =VLOOKUP(A19,[1]备料总表!$B:$I,4,0) -> 线缆 | E19: 广州 | F19: 1 | G19: 15 | H19: =VLOOKUP(B19,[2]各库区库存!$A:$B,2,0) -> 302-000471
A20: 302-000471 | B20: =A20 -> 302-000471 | C20: =VLOOKUP(A20,[1]备料总表!$B:$I,2,0) -> 电缆-SlimLine-Riser1_背板-R62X | D20: =VLOOKUP(A20,[1]备料总表!$B:$I,4,0) -> 线缆 | E20: 太原 | F20: 1 | G20: 8 | H20: =VLOOKUP(B20,[2]各库区库存!$A:$B,2,0) -> 302-000471
A21: 302-001139 | B21: =A21 -> 302-001139 | C21: =VLOOKUP(A21,[1]备料总表!$B:$I,2,0) -> S主板920X02K-5251K 4*(920,48C),4*GE | D21: =VLOOKUP(A21,[1]备料总表!$B:$I,4,0) -> 主板 | E21: 呼和浩特 | F21: 1 | G21: nd3，北京有1共用 | H21: =VLOOKUP(B21,[2]各库区库存!$A:$B,2,0) -> 302-001139
A22: 302-001139 | B22: =A22 -> 302-001139 | C22: =VLOOKUP(A22,[1]备料总表!$B:$I,2,0) -> S主板920X02K-5251K 4*(920,48C),4*GE | D22: =VLOOKUP(A22,[1]备料总表!$B:$I,4,0) -> 主板 | E22: 哈尔滨 | F22: 1 | G22: nd14，北京1共用 | H22: =VLOOKUP(B22,[2]各库区库存!$A:$B,2,0) -> 302-001139
A23: 302-001139 | B23: =A23 -> 302-001139 | C23: =VLOOKUP(A23,[1]备料总表!$B:$I,2,0) -> S主板920X02K-5251K 4*(920,48C),4*GE | D23: =VLOOKUP(A23,[1]备料总表!$B:$I,4,0) -> 主板 | E23: 福州 | F23: 1 | G23: nd4，武汉人肉供应 | H23: =VLOOKUP(B23,[2]各库区库存!$A:$B,2,0) -> 302-001139
A24: 302-001139 | B24: =A24 -> 302-001139 | C24: =VLOOKUP(A24,[1]备料总表!$B:$I,2,0) -> S主板920X02K-5251K 4*(920,48C),4*GE | D24: =VLOOKUP(A24,[1]备料总表!$B:$I,4,0) -> 主板 | E24: 成都 | F24: 1 | G24: nd1，武汉人肉供应 | H24: =VLOOKUP(B24,[2]各库区库存!$A:$B,2,0) -> 302-001139
A25: 302-001139 | B25: =A25 -> 302-001139 | C25: =VLOOKUP(A25,[1]备料总表!$B:$I,2,0) -> S主板920X02K-5251K 4*(920,48C),4*GE | D25: =VLOOKUP(A25,[1]备料总表!$B:$I,4,0) -> 主板 | E25: 兰州 | F25: 1 | G25: nd1，武汉人肉供应 | H25: =VLOOKUP(B25,[2]各库区库存!$A:$B,2,0) -> 302-001139
A26: 302-001139 | B26: =A26 -> 302-001139 | C26: =VLOOKUP(A26,[1]备料总表!$B:$I,2,0) -> S主板920X02K-5251K 4*(920,48C),4*GE | D26: =VLOOKUP(A26,[1]备料总表!$B:$I,4,0) -> 主板 | E26: 厦门 | F26: 1 | G26: nd2，武汉人肉供应 | H26: =VLOOKUP(B26,[2]各库区库存!$A:$B,2,0) -> 302-001139
A27: 302-001139 | B27: =A27 -> 302-001139 | C27: =VLOOKUP(A27,[1]备料总表!$B:$I,2,0) -> S主板920X02K-5251K 4*(920,48C),4*GE | D27: =VLOOKUP(A27,[1]备料总表!$B:$I,4,0) -> 主板 | E27: 上海 | F27: 1 | G27: nd1，武汉人肉供应 | H27: =VLOOKUP(B27,[2]各库区库存!$A:$B,2,0) -> 302-001139
A28: 302-001139 | B28: =A28 -> 302-001139 | C28: =VLOOKUP(A28,[1]备料总表!$B:$I,2,0) -> S主板920X02K-5251K 4*(920,48C),4*GE | D28: =VLOOKUP(A28,[1]备料总表!$B:$I,4,0) -> 主板 | E28: 海口 | F28: 1 | G28: nd1，武汉人肉供应 | H28: =VLOOKUP(B28,[2]各库区库存!$A:$B,2,0) -> 302-001139
A29: 302-001139 | B29: =A29 -> 302-001139 | C29: =VLOOKUP(A29,[1]备料总表!$B:$I,2,0) -> S主板920X02K-5251K 4*(920,48C),4*GE | D29: =VLOOKUP(A29,[1]备料总表!$B:$I,4,0) -> 主板 | E29: 石家庄 | F29: 1 | G29: nd3，北京供应 | H29: =VLOOKUP(B29,[2]各库区库存!$A:$B,2,0) -> 302-001139
A30: 302-001139 | B30: =A30 -> 302-001139 | C30: =VLOOKUP(A30,[1]备料总表!$B:$I,2,0) -> S主板920X02K-5251K 4*(920,48C),4*GE | D30: =VLOOKUP(A30,[1]备料总表!$B:$I,4,0) -> 主板 | E30: 杭州 | F30: 1 | G30: nd2，武汉供应 | H30: =VLOOKUP(B30,[2]各库区库存!$A:$B,2,0) -> 302-001139
A31: 302-001139 | B31: =A31 -> 302-001139 | C31: =VLOOKUP(A31,[1]备料总表!$B:$I,2,0) -> S主板920X02K-5251K 4*(920,48C),4*GE | D31: =VLOOKUP(A31,[1]备料总表!$B:$I,4,0) -> 主板 | E31: 太原 | F31: 1 | G31: nd6，北京1共用 | H31: =VLOOKUP(B31,[2]各库区库存!$A:$B,2,0) -> 302-001139
A32: 302-001139 | B32: =A32 -> 302-001139 | C32: =VLOOKUP(A32,[1]备料总表!$B:$I,2,0) -> S主板920X02K-5251K 4*(920,48C),4*GE | D32: =VLOOKUP(A32,[1]备料总表!$B:$I,4,0) -> 主板 | E32: 贵阳 | F32: 1 | G32: nd3，武汉供应 | H32: =VLOOKUP(B32,[2]各库区库存!$A:$B,2,0) -> 302-001139
... A111: 302-004225 | B111: =A111 -> 302-004225 | C111: =VLOOKUP(A111,[1]备料总表!$B:$I,2,0) -> 高速板对板连接器模组-74-UBC 8X 直式-UBC 8X 直式-120mm-0.16mm-10mm-5000MB/s-1.57mm-电缆安装型-低成本 5Gbps 线缆-是 | D111: =VLOOKUP(A111,[1]备料总表!$B:$I,4,0) -> 线缆 | E111: 长春 | F111: 1 | G111: nd76，北京有1可供应，一汽大众OEM-920B设备,稀缺线缆 | H111: =VLOOKUP(B111,[2]各库区库存!$A:$B,2,0) -> 302-004225
A112: 302-000493 | B112: =VLOOKUP(A112,[1]备料总表!$B:$I,8,0) -> 88-000493 | C112: =VLOOKUP(A112,[1]备料总表!$B:$I,2,0) -> 背板-8SAS+12NVME-NVMe4.0 | D112: =VLOOKUP(A112,[1]备料总表!$B:$I,4,0) -> 机箱/硬盘背板 | E112: 广州 | F112: 1 | G112: nd15，联通项目，福州供应，稀缺件 | H112: =VLOOKUP(B112,[2]各库区库存!$A:$B,2,0) -> #N/A
A113: 302-000493 | B113: =VLOOKUP(A113,[1]备料总表!$B:$I,8,0) -> 88-000493 | C113: =VLOOKUP(A113,[1]备料总表!$B:$I,2,0) -> 背板-8SAS+12NVME-NVMe4.0 | D113: =VLOOKUP(A113,[1]备料总表!$B:$I,4,0) -> 机箱/硬盘背板 | E113: 呼和浩特 | F113: 1 | G113: nd4，北京供应 | H113: =VLOOKUP(B113,[2]各库区库存!$A:$B,2,0) -> #N/A
A114: 302-000493 | B114: =VLOOKUP(A114,[1]备料总表!$B:$I,8,0) -> 88-000493 | C114: =VLOOKUP(A114,[1]备料总表!$B:$I,2,0) -> 背板-8SAS+12NVME-NVMe4.0 | D114: =VLOOKUP(A114,[1]备料总表!$B:$I,4,0) -> 机箱/硬盘背板 | E114: 济南 | F114: 1 | G114: nd1，北京供应 | H114: =VLOOKUP(B114,[2]各库区库存!$A:$B,2,0) -> #N/A
A115: 302-000493 | B115: =VLOOKUP(A115,[1]备料总表!$B:$I,8,0) -> 88-000493 | C115: =VLOOKUP(A115,[1]备料总表!$B:$I,2,0) -> 背板-8SAS+12NVME-NVMe4.0 | D115: =VLOOKUP(A115,[1]备料总表!$B:$I,4,0) -> 机箱/硬盘背板 | E115: 厦门 | F115: 1 | G115: nd28，福州供应 | H115: =VLOOKUP(B115,[2]各库区库存!$A:$B,2,0) -> #N/A
A116: 302-000493 | B116: =VLOOKUP(A116,[1]备料总表!$B:$I,8,0) -> 88-000493 | C116: =VLOOKUP(A116,[1]备料总表!$B:$I,2,0) -> 背板-8SAS+12NVME-NVMe4.0 | D116: =VLOOKUP(A116,[1]备料总表!$B:$I,4,0) -> 机箱/硬盘背板 | E116: 长春 | F116: 1 | G116: nd36，北京或哈尔滨供应，一汽大众 | H116: =VLOOKUP(B116,[2]各库区库存!$A:$B,2,0) -> #N/A
A117: 302-000493 | B117: =VLOOKUP(A117,[1]备料总表!$B:$I,8,0) -> 88-000493 | C117: =VLOOKUP(A117,[1]备料总表!$B:$I,2,0) -> 背板-8SAS+12NVME-NVMe4.0 | D117: =VLOOKUP(A117,[1]备料总表!$B:$I,4,0) -> 机箱/硬盘背板 | E117: 太原 | F117: 1 | G117: nd8，北京供应 | H117: =VLOOKUP(B117,[2]各库区库存!$A:$B,2,0) -> #N/A
A118: 302-000493 | B118: =VLOOKUP(A118,[1]备料总表!$B:$I,8,0) -> 88-000493 | C118: =VLOOKUP(A118,[1]备料总表!$B:$I,2,0) -> 背板-8SAS+12NVME-NVMe4.0 | D118: =VLOOKUP(A118,[1]备料总表!$B:$I,4,0) -> 机箱/硬盘背板 | E118: 西安 | F118: 1 | G118: nd4，武汉供应 | H118: =VLOOKUP(B118,[2]各库区库存!$A:$B,2,0) -> #N/A
...
